Workbook

Sheet Empreendimentos
A1: DIVISÃO DE AREAS PARA TORRES
A2: Master Plan - Rev06
A3: Data: 03/11/25
A5: ITEM | B5: QUADRAS / LOTE | E5: COEFICIENTE URBANISTICO | H5: ÁREAS | J5: TERRENO | L5: EDIFICIOS
B6: n° | C6: uso | D6: área | E6: coef. restrição | F6: % aprov. | G6: coef. considerado | H6: privativa | I6: construída | J6: unid. | K6: área média | L6: unid. | M6: área média apto. | N6: apto. / andar | O6: nº de pav.
A8: AL'DORA TOWN - VERSAILLES | D8: =SUM(D9,D32,D34) -> 42784.62 | H8: =SUM(H9,H32,H34) -> 125684.4 | I8: =SUM(I9,I32,I34) -> 206039.99 | L8: =SUM(L9,L32,L34) -> 14 | Q8: =L8+L57+L76+L104+L130+L126 -> 135 | R8: =Q8*150*2.8 -> 56700
A9: 1.0 | B9: QC01 | C9: Resid. Multifamiliar | D9: =SUM(D10:D30) -> 20598.71 | H9: =SUM(H10:H30) -> 49908.032 | I9: =SUM(I10:I30) -> 81816.446 | L9: =SUM(L10:L30) -> 6 | M9: =H9/N9 -> 75.848073 | N9: =SUMPRODUCT(N10:N30,O10:O30) -> 658
B10: LT01 | C10: Resid. Multifamiliar | D10: 1802.63 | E10: 4 | F10: 0.8 | G10: =E10*F10 -> 3.2 | H10: =D10*G10 -> 5768.416 | I10: =H10/0.61 -> 9456.4197 | J10: 1 | K10: =D10/J10 -> 1802.63 | L10: =J10 -> 1 | M10: =H10/(N10*O10) -> 56.553098 | N10: 6 | O10: 17
B11: LT02 | C11: Resid. Multifamiliar | D11: 2413.25 | E11: 4 | F11: 0.8 | G11: =E11*F11 -> 3.2 | H11: =D11*G11 -> 7722.4 | I11: =H11/0.61 -> 12659.672 | J11: 1 | K11: =D11/J11 -> 2413.25 | L11: =J11 -> 1 | M11: =H11/(N11*O11) -> 64.353333 | N11: 6 | O11: 20
B12: LT03 | C12: Lote misto - Venda | D12: 360 | J12: 1 | K12: =D12/J12 -> 360
B13: LT04 | C13: Lote misto - Venda | D13: 360 | J13: 1 | K13: =D13/J13 -> 360
B14: LT05 | C14: Lote misto - Venda | D14: 360 | J14: 1 | K14: =D14/J14 -> 360
B15: LT06 | C15: Lote misto - Venda | D15: 360 | J15: 1 | K15: =D15/J15 -> 360
B16: LT07 | C16: Lote misto - Venda | D16: 360 | J16: 1 | K16: =D16/J16 -> 360
B17: LT08 | C17: Lote misto - Venda | D17: 360 | J17: 1 | K17: =D17/J17 -> 360
B18: LT09 | C18: Lote misto - Venda | D18: 360 | J18: 1 | K18: =D18/J18 -> 360
B19: LT10 | C19: Resid. Multifamiliar | D19: 2423.05 | E19: 4 | F19: 0.8 | G19: =E19*F19 -> 3.2 | H19: =D19*G19 -> 7753.76 | I19: =H19/0.61 -> 12711.082 | J19: 1 | K19: =D19/J19 -> 2423.05 | L19: =J19 -> 1 | M19: =H19/(N19*O19) -> 64.614667 | N19: 6 | O19: 20
B20: LT11 | C20: Resid. Multifamiliar | D20: 2652.8 | E20: 4 | F20: 0.8 | G20: =E20*F20 -> 3.2 | H20: =D20*G20 -> 8488.96 | I20: =H20/0.61 -> 13916.328 | J20: 1 | K20: =D20/J20 -> 2652.8 | L20: =J20 -> 1 | M20: =H20/(N20*O20) -> 70.741333 | N20: 6 | O20: 20
B21: LT12 | C21: Lote misto - Venda | D21: 360 | J21: 1 | K21: =D21/J21 -> 360
B22: LT13 | C22: Lote misto - Venda | D22: 360 | J22: 1 | K22: =D22/J22 -> 360
B23: LT14 | C23: Lote misto - Venda | D23: 360 | J23: 1 | K23: =D23/J23 -> 360
B24: LT15 | C24: Lote misto - Venda | D24: 360 | J24: 1 | K24: =D24/J24 -> 360
B25: LT16 | C25: Lote misto - Venda | D25: 360 | J25: 1 | K25: =D25/J25 -> 360
B26: LT17 | C26: Lote misto - Venda | D26: 360 | J26: 1 | K26: =D26/J26 -> 360
B27: LT18 | C27: Lote misto - Venda | D27: 360 | J27: 1 | K27: =D27/J27 -> 360
B28: LT19 | C28: Lote misto - Venda | D28: 360 | J28: 1 | K28: =D28/J28 -> 360
B29: LT20 | C29: Resid. Multifamiliar | D29: 2726.58 | E29: 4 | F29: 0.8 | G29: =E29*F29 -> 3.2 | H29: =D29*G29 -> 8725.056 | I29: =H29/0.61 -> 14303.37 | J29: 1 | K29: =D29/J29 -> 2726.58 | L29: =J29 -> 1 | M29: =H29/(N29*O29) -> 87.25056 | N29: 5 | O29: 20
B30: LT21 | C30: Resid. Multifamiliar com fachada ativa | D30: 3180.4 | E30: 4 | F30: 0.9 | G30: =E30*F30 -> 3.6 | H30: =D30*G30 -> 11449.44 | I30: =H30/0.61 -> 18769.574 | J30: 1 | K30: =D30/J30 -> 3180.4 | L30: =J30 -> 1 | M30: =H30/(N30*O30) -> 119.265 | N30: 4 | O30: 24
A32: 2.0 | B32: QC02 | C32: Resid. Multifamiliar com fachada ativa | D32: 11953.63 | E32: 4 | F32: 0.9 | G32: =E32*F32 -> 3.6 | H32: =D32*G32 -> 43033.068 | I32: =H32/0.61 -> 70546.013 | J32: 4 | K32: =D32/J32 -> 2988.4075 | L32: =J32 -> 4 | M32: =(H32/L32)/(N32*O32) -> 112.06528 | N32: 4 | O32: 24
A34: 3.0 | B34: QC03 | C34: Resid. Multifamiliar com fachada ativa | D34: =10232.28 -> 10232.28 | E34: 4 | F34: 0.8 | G34: =E34*F34 -> 3.2 | H34: =D34*G34 -> 32743.296 | I34: =H34/0.61 -> 53677.534 | J34: 4 | K34: =D34/J34 -> 2558.07 | L34: =J34 -> 4 | M34: =(H34/L34)/(N34*O34) -> 102.3228 | N34: 4 | O34: 20
A36: 4.0 | B36: AI | C36: Park | D36: =(602-30)*30 -> 17160 | F36: =(D36/(20598.71+D32+D34)) -> 0.40107871
C37: Núcleo recreativos e cultural | D37: =100*3+3000 -> 3300 | F37: =(D37/(20598.71+D32+D34)) -> 0.07713052
C38: Paisagismos e caminhos verdes e culturais | D38: =D36-D37 -> 13860
A41: JARDIM CHAMBORD
A42: 1.0 | B42: JC | D42: =SUM(D43:D54) -> 128940.25 | H42: =SUM(H43:H54) -> 128940.25 | I42: =SUM(I43:I54) -> 0 | J42: =SUM(J43:J54) -> 208 | K42: =H42/J42 -> 619.90505
B43: Q01 | C43: Residencial unifamiliar | D43: 3016.52 | H43: =D43 -> 3016.52 | J43: 5 | K43: =D43/J43 -> 603.304 | Q43: =55*6 -> 330
B44: Q02 | C44: Residencial unifamiliar | D44: 13591.31 | H44: =D44 -> 13591.31 | J44: 22 | K44: =D44/J44 -> 617.78682
B45: Q03 | C45: Residencial unifamiliar | D45: 11309.04 | H45: =D45 -> 11309.04 | J45: 18 | K45: =D45/J45 -> 628.28
B46: Q04 | C46: Residencial unifamiliar | D46: 13413.04 | H46: =D46 -> 13413.04 | J46: 20 | K46: =D46/J46 -> 670.652
B47: Q05 | C47: Residencial unifamiliar | D47: 9773.57 | H47: =D47 -> 9773.57 | J47: 17 | K47: =D47/J47 -> 574.91588
...

Sheet Cromograma Fisico Financeiro
A2: CRONOGRAMA FÍSICO-FINANCEIRO
A3: CLIENTE: | B3: CIDADE JARDIM EMPREENDIMENTOS
A4: OBRA: | B4: AL' DORA CIDADE JARDIM
A5: DATA | B5: 45968
A6: REVISÃO: | B6: 01
A8: DISCRIMINAÇÃO | C8: PADRÃO | D8: EDIFICIO | E8: =Empreendimentos!H5 -> ÁREAS | H8: VALORES ( R$ ) | J8: ( % ) | L8: 1° ano | M8: 2° ano | N8: 3° ano | O8: 4° ano | P8: 5° ano | Q8: 6° ano | R8: 7° ano | S8: 8° ano | T8: 9° ano | U8: 10° ano | V8: 11° ano | W8: 12° ano | X8: 13° ano | Y8: 14° ano | Z8: 15° ano | AA8: 16° ano | AB8: 17° ano | AC8: 18° ano | AD8: 19° ano | AE8: 20° ano | AF8: 21° ano | AG8: 22° ano | AH8: 23° ano | AI8: 24° ano | AJ8: 25° ano | AK8: 26° | AL8: 27 | AM8: 28 | AN8: 29 | AO8: 30 | AP8: 31 | AQ8: 32 | AR8: 33 | AS8: 34 | AT8: 35 | AU8: 36 | AV8: 37 | AW8: 38 | AX8: 39 | AY8: 40 | AZ8: 41 | BA8: 42 | BB8: 43 | BC8: 44 | BD8: 45 | BE8: 46 | BF8: 47 | BG8: 48 | BH8: 49 | BI8: 50° ano
E9: unid. | F9: =Empreendimentos!H6 -> privativa | G9: =Empreendimentos!I6 -> construída | H9: VGV | I9: OBRA | J9: =H9 -> VGV | K9: =I9 -> OBRA | L9: 2026 | M9: 2027 | N9: 2028 | O9: 2029 | P9: 2030 | Q9: 2031 | R9: 2032 | S9: 2033 | T9: 2034 | U9: 2035 | V9: 2036 | W9: 2037 | X9: 2038 | Y9: 2039 | Z9: 2040 | AA9: 2041 | AB9: 2042 | AC9: 2043 | AD9: 2044 | AE9: 2045 | AF9: 2046 | AG9: 2047 | AH9: 2048 | AI9: 2049 | AJ9: 2050 | AK9: 2051 | AL9: 2052 | AM9: 2053 | AN9: 2054 | AO9: 2055 | AP9: 2056 | AQ9: 2057 | AR9: 2058 | AS9: 2059 | AT9: 2060 | AU9: 2061 | AV9: 2062 | AW9: 2063 | AX9: 2064 | AY9: 2065 | AZ9: 2066 | BA9: 2067 | BB9: 2068 | BC9: 2069 | BD9: 2070 | BE9: 2071 | BF9: 2072 | BG9: 2073 | BH9: 2074 | BI9: 2075
A11: 1.0 | B11: =Empreendimentos!A8 -> AL'DORA TOWN - VERSAILLES | D11: =Empreendimentos!L8 -> 14 | F11: =Empreendimentos!H8 -> 125684.4 | G11: =Empreendimentos!I8 -> 206039.99 | H11: =SUM(H12,H35,H37,H39) -> 1116394988 | I11: =SUM(I12,I35,I37,I39) -> 6.1583839e+08 | J11: =H11/$H$42 -> 1 | K11: =I11/$I$47 -> 1 | BJ11: =SUM(L11:BI11) -> 0
A12: =Empreendimentos!B9 -> QC01 | B12: =Empreendimentos!C9 -> Resid. Multifamiliar | C12: Standart Plus / Médio | D12: =Empreendimentos!L9 -> 6 | E12: =Empreendimentos!M9 -> 75.848073 | F12: =Empreendimentos!H9 -> 49908.032 | G12: =Empreendimentos!I9 -> 81816.446 | H12: =SUM(H13:H33) -> 4.3440771e+08 | I12: =SUM(I13:I33) -> 2.3969609e+08 | J12: =H12/$H$42 -> 0.3891165 | K12: =I12/$I$47 -> 0.38921915 | BJ12: =SUM(L12:BI12) -> 0
A13: =Empreendimentos!B10 -> LT01 | B13: =Empreendimentos!C10 -> Resid. Multifamiliar | C13: =$C$338 -> Standart Plus | D13: =Empreendimentos!L10 -> 1 | E13: =Empreendimentos!M10 -> 56.553098 | F13: =Empreendimentos!H10 -> 5768.416 | G13: =Empreendimentos!I10 -> 9456.4197 | H13: =F13*VLOOKUP(C13,$C$337:$E$344,2,FALSE) -> 46147328 | I13: =G13*VLOOKUP(C13,$C$337:$E$344,3,FALSE) -> 26556297 | J13: =H13/$H$42 -> 0.041336022 | K13: =I13/$I$47 -> 0.043122185 | L13: 0.02 | M13: 0.03 | N13: 0.04 | O13: 0.06 | P13: 0.07 | Q13: 0.08 | R13: 0.1 | S13: 0.1 | T13: 0.11 | U13: 0.1 | V13: 0.1 | W13: 0.08 | X13: 0.06 | Y13: 0.04 | Z13: 0.01 | BJ13: =SUM(L13:BI13) -> 1
A14: =Empreendimentos!B11 -> LT02 | B14: =Empreendimentos!C11 -> Resid. Multifamiliar | C14: =$C$338 -> Standart Plus | D14: =Empreendimentos!L11 -> 1 | E14: =Empreendimentos!M11 -> 64.353333 | F14: =Empreendimentos!H11 -> 7722.4 | G14: =Empreendimentos!I11 -> 12659.672 | H14: =F14*VLOOKUP(C14,$C$337:$E$344,2,FALSE) -> 61779200 | I14: =G14*VLOOKUP(C14,$C$337:$E$344,3,FALSE) -> 35551934 | J14: =H14/$H$42 -> 0.05533812 | K14: =I14/$I$47 -> 0.057729325 | L14: 0.02 | M14: 0.03 | N14: 0.04 | O14: 0.06 | P14: 0.07 | Q14: 0.08 | R14: 0.1 | S14: 0.1 | T14: 0.11 | U14: 0.1 | V14: 0.1 | W14: 0.08 | X14: 0.06 | Y14: 0.04 | Z14: 0.01 | BJ14: =SUM(L14:BI14) -> 1
A15: =Empreendimentos!B12 -> LT03 | B15: =Empreendimentos!C12 -> Lote misto - Venda | C15: =$C$343 -> Lote aberto | E15: =Empreendimentos!M12 -> 0 | F15: =Empreendimentos!D12 -> 360 | G15: =Empreendimentos!I12 -> 0 | H15: =F15*VLOOKUP(C15,$C$337:$E$344,2,FALSE) -> 432000 | I15: =G15*VLOOKUP(C15,$C$337:$E$344,3,FALSE) -> 0 | J15: =H15/$H$42 -> 0.00038695982 | K15: =I15/$I$47 -> 0 | L15: 1 | BJ15: =SUM(L15:BI15) -> 1
A16: =Empreendimentos!B13 -> LT04 | B16: =Empreendimentos!C13 -> Lote misto - Venda | C16: =$C$343 -> Lote aberto | E16: =Empreendimentos!M13 -> 0 | F16: =Empreendimentos!D13 -> 360 | G16: =Empreendimentos!I13 -> 0 | H16: =F16*VLOOKUP(C16,$C$337:$E$344,2,FALSE) -> 432000 | I16: =G16*VLOOKUP(C16,$C$337:$E$344,3,FALSE) -> 0 | J16: =H16/$H$42 -> 0.00038695982 | K16: =I16/$I$47 -> 0 | L16: 1 | BJ16: =SUM(L16:BI16) -> 1
A17: =Empreendimentos!B14 -> LT05 | B17: =Empreendimentos!C14 -> Lote misto - Venda | C17: =$C$343 -> Lote aberto | E17: =Empreendimentos!M14 -> 0 | F17: =Empreendimentos!D14 -> 360 | G17: =Empreendimentos!I14 -> 0 | H17: =F17*VLOOKUP(C17,$C$337:$E$344,2,FALSE) -> 432000 | I17: =G17*VLOOKUP(C17,$C$337:$E$344,3,FALSE) -> 0 | J17: =H17/$H$42 -> 0.00038695982 | K17: =I17/$I$47 -> 0 | L17: 1 | BJ17: =SUM(L17:BI17) -> 1
A18: =Empreendimentos!B15 -> LT06 | B18: =Empreendimentos!C15 -> Lote misto - Venda | C18: =$C$343 -> Lote aberto | E18: =Empreendimentos!M15 -> 0 | F18: =Empreendimentos!D15 -> 360 | G18: =Empreendimentos!I15 -> 0 | H18: =F18*VLOOKUP(C18,$C$337:$E$344,2,FALSE) -> 432000 | I18: =G18*VLOOKUP(C18,$C$337:$E$344,3,FALSE) -> 0 | J18: =H18/$H$42 -> 0.00038695982 | K18: =I18/$I$47 -> 0 | L18: 1 | BJ18: =SUM(L18:BI18) -> 1
A19: =Empreendimentos!B16 -> LT07 | B19: =Empreendimentos!C16 -> Lote misto - Venda | C19: =$C$343 -> Lote aberto | E19: =Empreendimentos!M16 -> 0 | F19: =Empreendimentos!D16 -> 360 | G19: =Empreendimentos!I16 -> 0 | H19: =F19*VLOOKUP(C19,$C$337:$E$344,2,FALSE) -> 432000 | I19: =G19*VLOOKUP(C19,$C$337:$E$344,3,FALSE) -> 0 | J19: =H19/$H$42 -> 0.00038695982 | K19: =I19/$I$47 -> 0 | L19: 1 | BJ19: =SUM(L19:BI19) -> 1
A20: =Empreendimentos!B17 -> LT08 | B20: =Empreendimentos!C17 -> Lote misto - Venda | C20: =$C$343 -> Lote aberto | E20: =Empreendimentos!M17 -> 0 | F20: =Empreendimentos!D17 -> 360 | G20: =Empreendimentos!I17 -> 0 | H20: =F20*VLOOKUP(C20,$C$337:$E$344,2,FALSE) -> 432000 | I20: =G20*VLOOKUP(C20,$C$337:$E$344,3,FALSE) -> 0 | J20: =H20/$H$42 -> 0.00038695982 | K20: =I20/$I$47 -> 0 | L20: 1 | BJ20: =SUM(L20:BI20) -> 1
A21: =Empreendimentos!B18 -> LT09 | B21: =Empreendimentos!C18 -> Lote misto - Venda | C21: =$C$343 -> Lote aberto | E21: =Empreendimentos!M18 -> 0 | F21: =Empreendimentos!D18 -> 360 | G21: =Empreendimentos!I18 -> 0 | H21: =F21*VLOOKUP(C21,$C$337:$E$344,2,FALSE) -> 432000 | I21: =G21*VLOOKUP(C21,$C$337:$E$344,3,FALSE) -> 0 | J21: =H21/$H$42 -> 0.00038695982 | K21: =I21/$I$47 -> 0 | L21: 1 | BJ21: =SUM(L21:BI21) -> 1
A22: =Empreendimentos!B19 -> LT10 | B22: =Empreendimentos!C19 -> Resid. Multifamiliar | C22: =$C$338 -> Standart Plus | D22: =Empreendimentos!L19 -> 1 | E22: =Empreendimentos!M19 -> 64.614667 | F22: =Empreendimentos!H19 -> 7753.76 | G22: =Empreendimentos!I19 -> 12711.082 | H22: =F22*VLOOKUP(C22,$C$337:$E$344,2,FALSE) -> 62030080 | I22: =G22*VLOOKUP(C22,$C$337:$E$344,3,FALSE) -> 35696308 | J22: =H22/$H$42 -> 0.055562843 | K22: =I22/$I$47 -> 0.057963759 | L22: 0.02 | M22: 0.03 | N22: 0.04 | O22: 0.06 | P22: 0.07 | Q22: 0.08 | R22: 0.1 | S22: 0.1 | T22: 0.11 | U22: 0.1 | V22: 0.1 | W22: 0.08 | X22: 0.06 | Y22: 0.04 | Z22: 0.01 | BJ22: =SUM(L22:BI22) -> 1
A23: =Empreendimentos!B20 -> LT11 | B23: =Empreendimentos!C20 -> Resid. Multifamiliar | C23: =$C$339 -> Médio | D23: =Empreendimentos!L20 -> 1 | E23: =Empreendimentos!M20 -> 70.741333 | F23: =Empreendimentos!H20 -> 8488.96 | G23: =Empreendimentos!I20 -> 13916.328 | H23: =F23*VLOOKUP(C23,$C$337:$E$344,2,FALSE) -> 76400640 | I23: =G23*VLOOKUP(C23,$C$337:$E$344,3,FALSE) -> 42022558 | J23: =H23/$H$42 -> 0.068435133 | K23: =I23/$I$47 -> 0.06823634 | L23: 0.02 | M23: 0.03 | N23: 0.04 | O23: 0.06 | P23: 0.07 | Q23: 0.08 | R23: 0.1 | S23: 0.1 | T23: 0.11 | U23: 0.1 | V23: 0.1 | W23: 0.08 | X23: 0.06 | Y23: 0.04 | Z23: 0.01 | BJ23: =SUM(L23:BI23) -> 1
A24: =Empreendimentos!B21 -> LT12 | B24: =Empreendimentos!C21 -> Lote misto - Venda | C24: =$C$343 -> Lote aberto | D24: =Empreendimentos!L21 -> 0 | E24: =Empreendimentos!M21 -> 0 | F24: =Empreendimentos!D21 -> 360 | G24: =Empreendimentos!I21 -> 0 | H24: =F24*VLOOKUP(C24,$C$337:$E$344,2,FALSE) -> 432000 | I24: =G24*VLOOKUP(C24,$C$337:$E$344,3,FALSE) -> 0 | J24: =H24/$H$42 -> 0.00038695982 | K24: =I24/$I$47 -> 0 | L24: 1 | BJ24: =SUM(L24:BI24) -> 1
A25: =Empreendimentos!B22 -> LT13 | B25: =Empreendimentos!C22 -> Lote misto - Venda | C25: =$C$343 -> Lote aberto | D25: =Empreendimentos!L22 -> 0 | E25: =Empreendimentos!M22 -> 0 | F25: =Empreendimentos!D22 -> 360 | G25: =Empreendimentos!I22 -> 0 | H25: =F25*VLOOKUP(C25,$C$337:$E$344,2,FALSE) -> 432000 | I25: =G25*VLOOKUP(C25,$C$337:$E$344,3,FALSE) -> 0 | J25: =H25/$H$42 -> 0.00038695982 | K25: =I25/$I$47 -> 0 | L25: 1 | BJ25: =SUM(L25:BI25) -> 1
A26: =Empreendimentos!B23 -> LT14 | B26: =Empreendimentos!C23 -> Lote misto - Venda | C26: =$C$343 -> Lote aberto | D26: =Empreendimentos!L23 -> 0 | E26: =Empreendimentos!M23 -> 0 | F26: =Empreendimentos!D23 -> 360 | G26: =Empreendimentos!I23 -> 0 | H26: =F26*VLOOKUP(C26,$C$337:$E$344,2,FALSE) -> 432000 | I26: =G26*VLOOKUP(C26,$C$337:$E$344,3,FALSE) -> 0 | J26: =H26/$H$42 -> 0.00038695982 | K26: =I26/$I$47 -> 0 | L26: 1 | BJ26: =SUM(L26:BI26) -> 1
A27: =Empreendimentos!B24 -> LT15 | B27: =Empreendimentos!C24 -> Lote misto - Venda | C27: =$C$343 -> Lote aberto | D27: =Empreendimentos!L24 -> 0 | E27: =Empreendimentos!M24 -> 0 | F27: =Empreendimentos!D24 -> 360 | G27: =Empreendimentos!I24 -> 0 | H27: =F27*VLOOKUP(C27,$C$337:$E$344,2,FALSE) -> 432000 | I27: =G27*VLOOKUP(C27,$C$337:$E$344,3,FALSE) -> 0 | J27: =H27/$H$42 -> 0.00038695982 | K27: =I27/$I$47 -> 0 | L27: 1 | BJ27: =SUM(L27:BI27) -> 1
A28: =Empreendimentos!B25 -> LT16 | B28: =Empreendimentos!C25 -> Lote misto - Venda | C28: =$C$343 -> Lote aberto | D28: =Empreendimentos!L25 -> 0 | E28: =Empreendimentos!M25 -> 0 | F28: =Empreendimentos!D25 -> 360 | G28: =Empreendimentos!I25 -> 0 | H28: =F28*VLOOKUP(C28,$C$337:$E$344,2,FALSE) -> 432000 | I28: =G28*VLOOKUP(C28,$C$337:$E$344,3,FALSE) -> 0 | J28: =H28/$H$42 -> 0.00038695982 | K28: =I28/$I$47 -> 0 | L28: 1 | BJ28: =SUM(L28:BI28) -> 1
A29: =Empreendimentos!B26 -> LT17 | B29: =Empreendimentos!C26 -> Lote misto - Venda | C29: =$C$343 -> Lote aberto | D29: =Empreendimentos!L26 -> 0 | E29: =Empreendimentos!M26 -> 0 | F29: =Empreendimentos!D26 -> 360 | G29: =Empreendimentos!I26 -> 0 | H29: =F29*VLOOKUP(C29,$C$337:$E$344,2,FALSE) -> 432000 | I29: =G29*VLOOKUP(C29,$C$337:$E$344,3,FALSE) -> 0 | J29: =H29/$H$42 -> 0.00038695982 | K29: =I29/$I$47 -> 0 | L29: 1 | BJ29: =SUM(L29:BI29) -> 1
A30: =Empreendimentos!B27 -> LT18 | B30: =Empreendimentos!C27 -> Lote misto - Venda | C30: =$C$343 -> Lote aberto | D30: =Empreendimentos!L27 -> 0 | E30: =Empreendimentos!M27 -> 0 | F30: =Empreendimentos!D27 -> 360 | G30: =Empreendimentos!I27 -> 0 | H30: =F30*VLOOKUP(C30,$C$337:$E$344,2,FALSE) -> 432000 | I30: =G30*VLOOKUP(C30,$C$337:$E$344,3,FALSE) -> 0 | J30: =H30/$H$42 -> 0.00038695982 | K30: =I30/$I$47 -> 0 | L30: 1 | BJ30: =SUM(L30:BI30) -> 1
A31: =Empreendimentos!B28 -> LT19 | B31: =Empreendimentos!C28 -> Lote misto - Venda | C31: =$C$343 -> Lote aberto | D31: =Empreendimentos!L28 -> 0 | E31: =Empreendimentos!M28 -> 0 | F31: =Empreendimentos!D28 -> 360 | G31: =Empreendimentos!I28 -> 0 | H31: =F31*VLOOKUP(C31,$C$337:$E$344,2,FALSE) -> 432000 | I31: =G31*VLOOKUP(C31,$C$337:$E$344,3,FALSE) -> 0 | J31: =H31/$H$42 -> 0.00038695982 | K31: =I31/$I$47 -> 0 | L31: 1 | BJ31: =SUM(L31:BI31) -> 1
A32: =Empreendimentos!B29 -> LT20 | B32: =Empreendimentos!C29 -> Resid. Multifamiliar | C32: =$C$339 -> Médio | D32: =Empreendimentos!L29 -> 1 | E32: =Empreendimentos!M29 -> 87.25056 | F32: =Empreendimentos!H29 -> 8725.056 | G32: =Empreendimentos!I29 -> 14303.37 | H32: =F32*VLOOKUP(C32,$C$337:$E$344,2,FALSE) -> 78525504 | I32: =G32*VLOOKUP(C32,$C$337:$E$344,3,FALSE) -> 43191294 | J32: =H32/$H$42 -> 0.07033846 | K32: =I32/$I$47 -> 0.070134138 | L32: 0.02 | M32: 0.03 | N32: 0.04 | O32: 0.06 | P32: 0.07 | Q32: 0.08 | R32: 0.1 | S32: 0.1 | T32: 0.11 | U32: 0.1 | V32: 0.1 | W32: 0.08 | X32: 0.06 | Y32: 0.04 | Z32: 0.01 | BJ32: =SUM(L32:BI32) -> 1
A33: =Empreendimentos!B30 -> LT21 | B33: =Empreendimentos!C30 -> Resid. Multifamiliar com fachada ativa | C33: =$C$339 -> Médio | D33: =Empreendimentos!L30 -> 1 | E33: =Empreendimentos!M30 -> 119.265 | F33: =Empreendimentos!H30 -> 11449.44 | G33: =Empreendimentos!I30 -> 18769.574 | H33: =F33*VLOOKUP(C33,$C$337:$E$344,2,FALSE) -> 103044960 | I33: =G33*VLOOKUP(C33,$C$337:$E$344,3,FALSE) -> 56677703 | J33: =H33/$H$42 -> 0.092301525 | K33: =I33/$I$47 -> 0.092033404 | L33: 0.02 | M33: 0.03 | N33: 0.04 | O33: 0.06 | P33: 0.07 | Q33: 0.08 | R33: 0.1 | S33: 0.1 | T33: 0.11 | U33: 0.1 | V33: 0.1 | W33: 0.08 | X33: 0.06 | Y33: 0.04 | Z33: 0.01 | BJ33: =SUM(L33:BI33) -> 1
A34: =Empreendimentos!B31 -> 0 | D34: =Empreendimentos!L31 -> 0 | E34: =Empreendimentos!M31 -> 0 | F34: =Empreendimentos!H31 -> 0 | G34: =Empreendimentos!I31 -> 0 | J34: =H34/$H$42 -> 0 | K34: =I34/$I$47 -> 0 | BJ34: =SUM(L34:BI34) -> 0
A35: =Empreendimentos!B32 -> QC02 | B35: =Empreendimentos!C32 -> Resid. Multifamiliar com fachada ativa | C35: =$C$339 -> Médio | D35: =Empreendimentos!L32 -> 4 | E35: =Empreendimentos!M32 -> 112.06528 | F35: =Empreendimentos!H32 -> 43033.068 | G35: =Empreendimentos!I32 -> 70546.013 | H35: =F35*VLOOKUP(C35,$C$337:$E$344,2,FALSE) -> 387297612 | I35: =G35*VLOOKUP(C35,$C$337:$E$344,3,FALSE) -> 2.1302487e+08 | J35: =H35/$H$42 -> 0.34691809 | K35: =I35/$I$47 -> 0.34591034 | L35: 0.02 | M35: 0.03 | N35: 0.04 | O35: 0.06 | P35: 0.07 | Q35: 0.08 | R35: 0.1 | S35: 0.1 | T35: 0.11 | U35: 0.1 | V35: 0.1 | W35: 0.08 | X35: 0.06 | Y35: 0.04 | Z35: 0.01 | BJ35: =SUM(L35:BI35) -> 1
A36: =Empreendimentos!B33 -> 0 | D36: =Empreendimentos!L33 -> 0 | E36: =Empreendimentos!M33 -> 0 | F36: =Empreendimentos!H33 -> 0 | G36: =Empreendimentos!I33 -> 0 | J36: =H36/$H$42 -> 0 | K36: =I36/$I$47 -> 0 | BJ36: =SUM(L36:BI36) -> 0
A37: =Empreendimentos!B34 -> QC03 | B37: =Empreendimentos!C34 -> Resid. Multifamiliar com fachada ativa | C37: =$C$339 -> Médio | D37: =Empreendimentos!L34 -> 4 | E37: =Empreendimentos!M34 -> 102.3228 | F37: =Empreendimentos!H34 -> 32743.296 | G37: =Empreendimentos!I34 -> 53677.534 | H37: =F37*VLOOKUP(C37,$C$337:$E$344,2,FALSE) -> 294689664 | I37: =G37*VLOOKUP(C37,$C$337:$E$351,3,FALSE) -> 1.6208782e+08 | J37: =H37/$H$42 -> 0.26396541 | K37: =I37/$I$47 -> 0.26319864 | L37: 0.02 | M37: 0.03 | N37: 0.04 | O37: 0.06 | P37: 0.07 | Q37: 0.08 | R37: 0.1 | S37: 0.1 | T37: 0.11 | U37: 0.1 | V37: 0.1 | W37: 0.08 | X37: 0.06 | Y37: 0.04 | Z37: 0.01 | BJ37: =SUM(L37:BI37) -> 1
D38: =Empreendimentos!L35 -> 0 | F38: =Empreendimentos!H35 -> 0 | G38: =Empreendimentos!I35 -> 0 | K38: =I38/$I$47 -> 0 | BJ38: =SUM(L38:BI38) -> 0
B39: Núcleo Recreativo e Cultural | C39: =C349 -> Parque Versailles | D39: =Empreendimentos!L36 -> 0 | E39: =Empreendimentos!M36 -> 0 | F39: =Empreendimentos!H36 -> 0 | G39: =Empreendimentos!D36 -> 17160 | H39: =F39*VLOOKUP(C39,$C$337:$E$351,2,FALSE) -> 0 | I39: =G39*VLOOKUP(C39,$C$337:$E$351,3,FALSE) -> 1029600 | J39: =H39/$H$42 -> 0 | K39: =I39/$I$47 -> 0.0016718672 | L39: 0.5 | M39: 0.5 | BJ39: =SUM(L39:BI39) -> 1
J40: =H40/$H$42 -> 0 | K40: =I40/$H$42 -> 0 | BJ40: =SUM(K40:AI40) -> 0
A42: TOTAL VGV | C42: TOTAIS SIMPLES | H42: =SUM(H12,H35,H37,H39) -> 1116394988 | J42: =SUM(J12,J35,J37) -> 1 | L42: =SUMPRODUCT($H11:$H40,L11:L40) -> 28678300 | M42: =SUMPRODUCT($H11:$H40,M11:M40) -> 33297450 | N42: =SUMPRODUCT($H11:$H40,N11:N40) -> 44396600 | O42: =SUMPRODUCT($H11:$H40,O11:O40) -> 66594899 | P42: =SUMPRODUCT($H11:$H40,P11:P40) -> 77694049 | Q42: =SUMPRODUCT($H11:$H40,Q11:Q40) -> 88793199 | R42: =SUMPRODUCT($H11:$H40,R11:R40) -> 1.109915e+08 | S42: =SUMPRODUCT($H11:$H40,S11:S40) -> 1.109915e+08 | ... BI42: =SUMPRODUCT($H11:$H40,BI11:BI40) -> 0
C43: TOTAIS ACUMULADOS | L43: =L42+J42 -> 28678301 | M43: =M42+L43 -> 61975750 | N43: =N42+M43 -> 1.0637235e+08 | O43: =O42+N43 -> 1.7296725e+08 | P43: =P42+O43 -> 2.506613e+08 | Q43: =Q42+P43 -> 3.394545e+08 | R43: =R42+Q43 -> 4.50446e+08 | S43: =S42+R43 -> 561437495 | T43: =T42+S43 -> 6.8352814e+08 | ... BI43: =BI42+BH43 -> 1116394989
C44: PERCENTUAL MENSAL | L44: =L42/$H$42 -> 0.025688309 | M44: =M42/$H$42 -> 0.029825868 | N44: =N42/$H$42 -> 0.039767824 | O44: =O42/$H$42 -> 0.059651736 | P44: =P42/$H$42 -> 0.069593692 | Q44: =Q42/$H$42 -> 0.079535648 | R44: =R42/$H$42 -> 0.09941956 | S44: =S42/$H$42 -> 0.09941956 | ... BI44: =BI42/$H$42 -> 0
...

Sheet GRAFICOS
B1: 1° ano | C1: 2° ano | D1: 3° ano | E1: 4° ano | F1: 5° ano | G1: 6° ano | H1: 7° ano | I1: 8° ano | J1: 9° ano | K1: 10° ano | L1: 11° ano | M1: 12° ano | N1: 13° ano | O1: 14° ano | P1: 15° ano | Q1: 16° ano | R1: 17° ano | S1: 18° ano | T1: 19° ano | U1: 20° ano
B2: 2026 | C2: 2027 | D2: 2028 | E2: 2029 | F2: 2030 | G2: 2031 | H2: 2032 | I2: 2033 | J2: 2034 | K2: 2035 | L2: 2036 | M2: 2037 | N2: 2038 | O2: 2039 | P2: 2040 | Q2: 2041 | R2: 2042 | S2: 2043 | T2: 2044 | U2: 2045
A3: VGV ANUAL | B3: ='Cromograma Fisico Financeiro'!L323/1000000000 -> 0.087990815 | C3: ='Cromograma Fisico Financeiro'!M323/1000000000 -> 0.23198899 | D3: ='Cromograma Fisico Financeiro'!N323/1000000000 -> 0.30265481 | E3: ='Cromograma Fisico Financeiro'!O323/1000000000 -> 0.2988923 | F3: ='Cromograma Fisico Financeiro'!P323/1000000000 -> 0.31209728 | G3: ='Cromograma Fisico Financeiro'!Q323/1000000000 -> 0.21227429 | H3: ='Cromograma Fisico Financeiro'!R323/1000000000 -> 0.28733944 | I3: ='Cromograma Fisico Financeiro'!S323/1000000000 -> 0.39925377 | ... U3: ='Cromograma Fisico Financeiro'!AE323/1000000000 -> 0.28783704
A4: VGV ACUMULADO | B4: ='Cromograma Fisico Financeiro'!L324/1000000000 -> 0.087990815 | C4: ='Cromograma Fisico Financeiro'!M324/1000000000 -> 0.31997981 | D4: ='Cromograma Fisico Financeiro'!N324/1000000000 -> 0.62263461 | E4: ='Cromograma Fisico Financeiro'!O324/1000000000 -> 0.92152691 | F4: ='Cromograma Fisico Financeiro'!P324/1000000000 -> 1.2336242 | G4: ='Cromograma Fisico Financeiro'!Q324/1000000000 -> 1.4458985 | H4: ='Cromograma Fisico Financeiro'!R324/1000000000 -> 1.7332379 | I4: ='Cromograma Fisico Financeiro'!S324/1000000000 -> 2.1324917 | ... U4: ='Cromograma Fisico Financeiro'!AE324/1000000000 -> 6.7973715
B39: 1° ano | C39: 5° ano | D39: 10° ano | E39: 20° ano
B40: 2026 | C40: =F2 -> 2030 | D40: =K2 -> 2035 | E40: =U2 -> 2045
A41: EMPREGOS ANUAL | B41: 2200 | C41: =31000-2000 -> 29000 | D41: =75200-29000 -> 46200 | E41: =170000-46200 -> 123800
A42: EMPREGOS ACUMULADO | B42: =B41 -> 2200 | C42: =B41+C41 -> 31200 | D42: =C41+D41 -> 75200 | E42: =D41+E41 -> 170000
B65: 1° ano | C65: 2° ano | D65: 3° ano | E65: 4° ano | F65: 5° ano | G65: 6° ano | H65: 7° ano | I65: 8° ano | J65: 9° ano | K65: 10° ano | L65: 11° ano | M65: 12° ano | N65: 13° ano | O65: 14° ano | P65: 15° ano | Q65: 16° ano | R65: 17° ano | S65: 18° ano | T65: 19° ano | U65: 20° ano
B66: 2026 | C66: 2027 | D66: 2028 | E66: 2029 | F66: 2030 | G66: 2031 | H66: 2032 | I66: 2033 | J66: 2034 | K66: 2035 | L66: 2036 | M66: 2037 | N66: 2038 | O66: 2039 | P66: 2040 | Q66: 2041 | R66: 2042 | S66: 2043 | T66: 2044 | U66: 2045
A67: INVESTIMENTOS ANUAL | B67: ='Cromograma Fisico Financeiro'!L328/1000000000 -> 0.024415598 | C67: ='Cromograma Fisico Financeiro'!M328/1000000000 -> 0.087573681 | D67: ='Cromograma Fisico Financeiro'!N328/1000000000 -> 0.16676675 | E67: ='Cromograma Fisico Financeiro'!O328/1000000000 -> 0.19298122 | F67: ='Cromograma Fisico Financeiro'!P328/1000000000 -> 0.19030309 | G67: ='Cromograma Fisico Financeiro'!Q328/1000000000 -> 0.20364209 | H67: ='Cromograma Fisico Financeiro'!R328/1000000000 -> 0.25844996 | I67: ='Cromograma Fisico Financeiro'!S328/1000000000 -> 0.28666898 | ... U67: ='Cromograma Fisico Financeiro'!AE328/1000000000 -> 0.26395422
A68: INVESTIMENTOS ACUM. | B68: =B67 -> 0.024415598 | C68: =B68+C67 -> 0.11198928 | D68: =C68+D67 -> 0.27875603 | E68: =D68+E67 -> 0.47173725 | F68: =E68+F67 -> 0.66204034 | G68: =F68+G67 -> 0.86568244 | H68: =G68+H67 -> 1.1241324 | I68: =H68+I67 -> 1.4108014 | J68: =I68+J67 -> 1.7428769 | ... U68: =T68+U67 -> 5.3196572

Sheet QUADRO DE ÁREAS e POPULAÇÃO
A1: ALDORA BOULEVARD
A3: Área Total | B3: 59743.74 | C3: 1 | F3: CALCULO CONFORME INDICE PREFEITURA
A4: Área Parcelável | B4: =B3 -> 59743.74 | C4: =B4/B3 -> 1 | F4: Área Líquida | G4: CA | H4: Área Construtiva | I4: Apartamento Padrão | J4: Nº de Apartamentos | K4: Morador por Domicílio (IBGE) | L4: População Prevista | M4: Densidade Líquida | P4: População Prevista
E5: Indice 4 | F5: =B8 -> 37412.41 | G5: 4 | H5: =G5*F5 -> 149649.64 | I5: 100 | J5: =H5/I5 -> 1496.4964 | K5: 2.8 | L5: =K5*J5 -> 4190.1899 | M5: =L5/F5*10000 -> 1120 | P5: =L5 -> 4190.1899
A6: Área a Parcelar | B6: =B4 -> 59743.74 | C6: 1
A7: Área Alienável | B7: =B8+B9 -> 42812.41 | C7: =B7/B6 -> 0.71660077 | F7: CALCULO COM DENSIDADE SUGERIDA
A8: Lotes Residenciais | B8: 37412.41 | C8: =B8/B6 -> 0.62621473 | F8: Densidade Líquida | G8: Área Habitacional Total | I8: População Prevista | J8: Morador por Domicílio (IBGE) | K8: Nº de Apartamentos | L8: Apartamento Padrão | M8: Área Construtiva | N8: CA
A9: Lotes Comerciais | B9: 5400 | C9: =B9/B6 -> 0.090386039 | F9: 600 | G9: =B8/10000 -> 3.741241 | I9: =G9*F9 -> 2244.7446 | J9: 2.8 | K9: =I9/J9 -> 801.6945 | L9: 100 | M9: =K9*L9 -> 80169.45 | N9: =(M9/G9)/10000 -> 2.1428571
A10: Área Verde | B10: 7741.42 | C10: =B10/B6 -> 0.12957709
A11: Sistema Viário | B11: =B6-B7-B10 -> 9189.91 | C11: =B11/B6 -> 0.15382214
A14: ALDORA TOWN
A16: Área Total | B16: 117208.4 | C16: 1 | F16: CALCULO CONFORME INDICE PREFEITURA
A17: Área Parcelável | B17: =B16 -> 117208.4 | C17: =B17/B16 -> 1 | F17: Área Líquida | G17: CA | H17: Área Construtiva | I17: Apartamento Padrão | J17: Nº de Apartamentos | K17: Morador por Domicílio (IBGE) | L17: População Prevista | M17: Densidade Líquida
E18: Indice 4 | F18: 31336.65 | G18: 4 | H18: =G18*F18 -> 125346.6 | I18: 100 | J18: =H18/I18 -> 1253.466 | K18: 2.8 | L18: =K18*J18 -> 3509.7048 | M18: =L18/F18*10000 -> 1120
A19: Área a Parcelar | B19: =B17 -> 117208.4 | C19: 1 | E19: Indice 3 | F19: =B21-F18 -> 9147.93 | G19: 3 | H19: =G19*F19 -> 27443.79 | J19: =H19/I18 -> 274.4379 | L19: =K18*J19 -> 768.42612 | M19: =L19/F19*10000 -> 840
A20: Área Alienável | B20: =B21+B22+B23+B24 -> 64758.75 | C20: =B20/B19 -> 0.55250946 | E20: Total | F20: =F18+F19 -> 40484.58 | L20: =L18+L19 -> 4278.1309 | M20: =L20/F20*10000 -> 1056.731 | P20: =L20 -> 4278.1309
A21: Lotes Residenciais | B21: 40484.58 | C21: =B21/B19 -> 0.34540681
A22: Mall | B22: 8925.08 | C22: =B22/B19 -> 0.076147102
A23: Educação | B23: 5942.25 | C23: =B23/B19 -> 0.050698158 | F23: CALCULO COM DENSIDADE SUGERIDA
A24: Office | B24: 9406.84 | C24: =B24/B19 -> 0.080257388 | F24: Densidade Líquida | G24: Área Habitacional Total | I24: População Prevista | J24: Morador por Domicílio (IBGE) | K24: Nº de Apartamentos | L24: Apartamento Padrão | M24: Área Construtiva | N24: CA
A25: Área Verde / Praça | B25: 7929.92 | C25: =B25/B19 -> 0.067656584 | F25: 600 | G25: =B21/10000 -> 4.048458 | I25: =G25*F25 -> 2429.0748 | J25: 2.8 | K25: =I25/J25 -> 867.52671 | L25: 100 | M25: =K25*L25 -> 86752.671 | N25: =(M25/G25)/10000 -> 2.1428571
A26: Sistema Viário | B26: =B19-B20-B25 -> 44519.73 | C26: =B26/B19 -> 0.37983395
A29: ALDORA PARK
F30: CALCULO CONFORME INDICE PREFEITURA
A31: Área Total | B31: 307286.3 | C31: 1 | F31: Área Líquida | G31: CA | H31: Área Construtiva | I31: Apartamento Padrão | J31: Nº de Apartamentos | K31: Morador por Domicílio (IBGE) | L31: População Prevista | M31: Densidade Líquida
A32: Área Parcelável | B32: =B31 -> 307286.3 | C32: =B32/B31 -> 1 | E32: Indice 4 | F32: 49877.37 | G32: 4 | H32: =G32*F32 -> 199509.48 | I32: 100 | J32: =H32/I32 -> 1995.0948 | K32: 2.8 | L32: =K32*J32 -> 5586.2654 | M32: =L32/F32*10000 -> 1120
E33: Indice 3 | F33: 89793.52 | G33: 3 | H33: =G33*F33 -> 269380.56 | J33: =H33/I32 -> 2693.8056 | L33: =K32*J33 -> 7542.6557 | M33: =L33/F33*10000 -> 840
A34: Área a Parcelar | B34: =B32 -> 307286.3 | C34: 1 | E34: Total | F34: =F32+F33 -> 139670.89 | L34: =L32+L33 -> 13128.921 | M34: =L34/F34*10000 -> 939.98979 | P34: =L34 -> 13128.921
A35: Área Alienável | B35: =B36+B37 -> 150137.86 | C35: =B35/B34 -> 0.48859276
A36: Lotes Residenciais | B36: 139670.89 | C36: =B36/B34 -> 0.45453016
A37: Mall | B37: 10466.97 | C37: =B37/B34 -> 0.034062599 | F37: CALCULO COM DENSIDADE SUGERIDA
A38: Área Verde / Praça | B38: 67225.47 | C38: =B38/B34 -> 0.21877145 | F38: Densidade Líquida | G38: Área Habitacional Total | I38: População Prevista | J38: Morador por Domicílio (IBGE) | K38: Nº de Apartamentos | L38: Apartamento Padrão | M38: Área Construtiva | N38: CA
A39: Sistema Viário | B39: =B34-B35-B38 -> 89922.97 | C39: =B39/B34 -> 0.29263579 | F39: 600 | G39: =B36/10000 -> 13.967089 | I39: =G39*F39 -> 8380.2534 | J39: 2.8 | K39: =I39/J39 -> 2992.9476 | L39: 100 | M39: =K39*L39 -> 299294.76 | N39: =(M39/G39)/10000 -> 2.1428571
A42: ALDORA VITTA
A44: Área Total | B44: 285560.17 | C44: 1 | F44: CALCULO CONFORME INDICE PREFEITURA
A45: Área de Preversação Permanente | B45: 98424.41 | F45: Área Líquida | G45: CA | H45: Área Construtiva | I45: Apartamento Padrão | J45: Nº de Apartamentos | K45: Morador por Domicílio (IBGE) | L45: População Prevista | M45: Densidade Líquida
A46: Área Parcelável | B46: =B44-B45 -> 187135.76 | C46: =B46/B44 -> 0.65532865 | E46: Indice 4 | F46: 50947.26 | G46: 4 | H46: =G46*F46 -> 203789.04 | I46: 100 | J46: =H46/I46 -> 2037.8904 | K46: 2.8 | L46: =K46*J46 -> 5706.0931 | M46: =L46/F46*10000 -> 1120
E47: Indice 3 | F47: =B50-F46 -> 53456.07 | G47: 3 | H47: =G47*F47 -> 160368.21 | J47: =H47/I46 -> 1603.6821 | L47: =K46*J47 -> 4490.3099 | M47: =L47/F47*10000 -> 840
A48: Área a Parcelar | B48: =B46 -> 187135.76 | C48: 1 | E48: Total | F48: =F46+F47 -> 104403.33 | L48: =L46+L47 -> 10196.403 | M48: =L48/F48*10000 -> 976.6358 | P48: =L48 -> 10196.403
A49: Área Alienável | B49: =B50+B51 -> 112302.41 | C49: =B49/B48 -> 0.60011197
...

Sheet POPULAÇÃO ATENDIDA
A1: DADOS DEMOGRÁFICOS
A2: DISTRIBUIÇÃO E EVOLUÇÃO POPULACIONAL
A3: A população residente total na Área de Influência em 2017 é estimada em 103,7 mil habitantes, dos quais 89% estão na Área Secundária.
A4: População estimada 2025, 761.835 pessoas [2025]
C6: 2017 | E6: 2025
A7: Área de Influência | B7: TGCA* | C7: População | D7: Part. | E7: População | F7: Part.
A8: Primaria | B8: 0.079 | C8: 11816 | D8: =C8/C10 -> 0.11392869 | E8: =C8/$C$12*$E$12 -> 12943.873 | F8: =E8/E10 -> 0.11392869
A9: Secundaria | B9: 0.024 | C9: 91898 | D9: =C9/C10 -> 0.88607131 | E9: =C9/$C$12*$E$12 -> 100669.94 | F9: =E9/E10 -> 0.88607131
C10: =SUM(C8:C9) -> 103714 | D10: =SUM(D8:D9) -> 1 | E10: =SUM(E8:E9) -> 113613.82 | F10: =SUM(F8:F9) -> 1
A12: POPULAÇÃO | C12: 695452 | E12: 761835

Sheet Cronogramaa Fisico
A2: CRONOGRAMA FÍSICO-FINANCEIRO
A3: CLIENTE: | B3: CIDADE JARDIM EMPREENDIMENTOS
A4: OBRA: | B4: AL' DORA CIDADE JARDIM
A5: DATA | B5: 45968
A6: REVISÃO: | B6: 01
A8: DISCRIMINAÇÃO | C8: AREA | D8: 1° ano | E8: 2° ano | F8: 3° ano | G8: 4° ano | H8: 5° ano | I8: 6° ano | J8: 7° ano | K8: 8° ano | L8: 9° ano | M8: 10° ano | N8: 11° ano | O8: 12° ano | P8: 13° ano | Q8: 14° ano | R8: 15° ano | S8: 16° ano | T8: 17° ano | U8: 18° ano | V8: 19° ano | W8: 20° ano | X8: 21° ano | Y8: 22° ano | Z8: 23° ano | AA8: 24° ano | AB8: 25° ano | AC8: 26° | AD8: 27 | AE8: 28 | AF8: 29 | AG8: 30 | AH8: 31 | AI8: 32 | AJ8: 33 | AK8: 34 | AL8: 35 | AM8: 36 | AN8: 37 | AO8: 38 | AP8: 39 | AQ8: 40 | AR8: 41 | AS8: 42 | AT8: 43 | AU8: 44 | AV8: 45 | AW8: 46 | AX8: 47 | AY8: 48 | AZ8: 49 | BA8: 50° ano
D9: 2026 | E9: 2027 | F9: 2028 | G9: 2029 | H9: 2030 | I9: 2031 | J9: 2032 | K9: 2033 | L9: 2034 | M9: 2035 | N9: 2036 | O9: 2037 | P9: 2038 | Q9: 2039 | R9: 2040 | S9: 2041 | T9: 2042 | U9: 2043 | V9: 2044 | W9: 2045 | X9: 2046 | Y9: 2047 | Z9: 2048 | AA9: 2049 | AB9: 2050 | AC9: 2051 | AD9: 2052 | AE9: 2053 | AF9: 2054 | AG9: 2055 | AH9: 2056 | AI9: 2057 | AJ9: 2058 | AK9: 2059 | AL9: 2060 | AM9: 2061 | AN9: 2062 | AO9: 2063 | AP9: 2064 | AQ9: 2065 | AR9: 2066 | AS9: 2067 | AT9: 2068 | AU9: 2069 | AV9: 2070 | AW9: 2071 | AX9: 2072 | AY9: 2073 | AZ9: 2074 | BA9: 2076
B11: INFRA ESTRUTURA
A12: 1.0 | B12: FASE 01 - AL'DORA VERSAILLES | BB12: =SUM(D12:BA12) -> 0
A13: 1.1 | B13: Al'dora Town - Versailles | D13: 0.025688309 | E13: 0.045 | F13: 0.06 | G13: 0.08 | H13: 0.08 | I13: 0.09 | J13: 0.1 | K13: 0.11 | L13: 0.1 | M13: 0.09 | N13: 0.07 | O13: 0.07 | P13: 0.05 | Q13: 0.02 | R13: 0.009941956 | BB13: =SUM(D13:BA13) -> 1.0006303
BB14: =SUM(D14:BA14) -> 0
A15: 2.0 | B15: FASE 02 - JARDIM CHAMBORD / AL'DORA TOWN | BB15: =SUM(D15:BA15) -> 0
A16: 2.1 | B16: Jardim Chambord | D16: 0.2 | E16: 0.5 | F16: 0.3 | BB16: =SUM(D16:BA16) -> 1
A17: 2.2 | B17: Al'dora Town - Infra estrutura | E17: 0.4 | F17: 0.6 | BB17: =SUM(D17:BA17) -> 1
A18: 2.3 | B18: Mall | F18: 0.2 | G18: 0.4 | L18: 0.2 | M18: 0.2 | BB18: =SUM(D18:BA18) -> 1
A19: 2.4 | B19: Escolas | F19: 0.2 | G19: 0.3 | L19: 0.1 | M19: 0.4 | BB19: =SUM(D19:BA19) -> 1
A20: 2.5 | B20: Edificações | F20: 0.02 | G20: 0.03 | H20: 0.04 | I20: 0.06 | J20: 0.07 | K20: 0.08 | L20: 0.1 | M20: 0.1 | N20: 0.11 | O20: 0.1 | P20: 0.1 | Q20: 0.08 | R20: 0.06 | S20: 0.04 | T20: 0.01 | BB20: =SUM(D20:BA20) -> 1
BB21: =SUM(D21:BA21) -> 0
A22: 3.0 | B22: FASE 03 - JARDIM 03 | BB22: =SUM(D22:BA22) -> 0
A23: 3.1 | B23: Jardim Condomínio Fechado | F23: 0.3 | G23: 0.4 | H23: 0.3 | BB23: =SUM(D23:BA23) -> 1
BB24: =SUM(D24:BA24) -> 0
A25: 4.0 | B25: FASE 04 - INFRA ESTRUTURA - | BB25: =SUM(D25:BA25) -> 0
A26: 4.1 | B26: Gleba H - Etapa 01 | BB26: =SUM(D26:BA26) -> 0
B27: EEE e Coletor Tronco | F27: 0.4 | G27: 0.6 | BB27: =SUM(D27:BA27) -> 1
B28: Adutora | G28: 0.4 | H28: 0.6 | BB28: =SUM(D28:BA28) -> 1
A29: 4.2 | B29: Gleba 6 e 7 - Etapa 02 | BB29: =SUM(D29:BA29) -> 0
B30: EEE e Coletor Tronco | K30: 0.3 | L30: 0.7 | BB30: =SUM(D30:BA30) -> 1
B31: Adutora | K31: 0.3 | L31: 0.7 | BB31: =SUM(D31:BA31) -> 1
BB32: =SUM(D32:BA32) -> 0
A33: 5.0 | B33: FASE 05 - AL'DORA NEXUS GENOVA | BB33: =SUM(D33:BA33) -> 0
A34: 5.1 | B34: Polo Corporativo - Etapa 01, 02 e 03 | E34: 0.1 | F34: 0.125 | G34: 0.15 | H34: 0.1 | I34: 0.05 | J34: 0.05 | M34: 0.06 | N34: 0.14 | Q34: 0.085 | R34: 0.14 | BB34: =SUM(D34:BA34) -> 1
BB35: =SUM(D35:BA35) -> 0
A36: 6.0 | B36: FASE 06 - AL'DORA PARK | BB36: =SUM(D36:BA36) -> 0
A37: 6.1 | B37: Infra estrutura - Etapa 01, 02 e 03 | H37: 0.05 | I37: 0.2 | J37: 0.15 | O37: 0.2 | P37: 0.15 | S37: 0.15 | T37: 0.1 | BB37: =SUM(D37:BA37) -> 1
A38: 6.2 | B38: Edificações | J38: 0.01 | K38: 0.01 | L38: 0.01 | M38: 0.013 | N38: 0.02 | O38: 0.022 | P38: 0.025 | Q38: 0.03 | R38: 0.03 | S38: 0.03 | T38: 0.03 | U38: 0.03 | V38: 0.03 | W38: 0.03 | X38: 0.03 | Y38: 0.03 | Z38: 0.03 | AA38: 0.03 | AB38: 0.03 | AC38: 0.03 | AD38: 0.03 | AE38: 0.03 | AF38: 0.03 | AG38: 0.02 | AH38: 0.02 | AI38: 0.02 | AJ38: 0.02 | AK38: 0.02 | AL38: 0.02 | AM38: 0.02 | AN38: 0.02 | AO38: 0.02 | AP38: 0.02 | AQ38: 0.02 | AR38: 0.02 | AS38: 0.02 | AT38: 0.02 | AU38: 0.02 | AV38: 0.02 | AW38: 0.02 | AX38: 0.02 | AY38: 0.02 | AZ38: 0.02 | BA38: 0.01 | BB38: =SUM(D38:BA38) -> 1
BB39: =SUM(D39:BA39) -> 0
A40: 7.0 | B40: FASE 07 - JARDIM 04 | BB40: =SUM(D40:BA40) -> 0
A41: 71 | B41: Jardim Condomínio Fechado | K41: 0.4 | L41: 0.6 | BB41: =SUM(D41:BA41) -> 1
BB42: =SUM(D42:BA42) -> 0
A43: 8.0 | B43: FASE 08 - AL'DORA NEXUS | BB43: =SUM(D43:BA43) -> 0
...

Sheet Referencias
A3: Empreendimento Incorporadora | B3: Área privativa(AP) (m²) | C3: Área total geral(AT) (m²) | D3: Área do terreno (m²) | E3: N° unidades
A4: Domum Bild | B4: 15366.36 | C4: 26875.46 | D4: 4793.31 | E4: 126 | F4: =B4/D4 -> 3.2057931
A5: GrandVerse Place Perplan | B5: 16991.98 | C5: 26758.88 | D5: 4439.5 | E5: 156 | F5: =B5/D5 -> 3.8274535
A6: Casa'Alta Perplan | B6: 13386.08 | C6: 22689.57 | D6: 4000 | F6: =B6/D6 -> 3.34652
A7: Nuage Perplan | B7: 11659.35 | C7: 19618.39 | D7: 3100 | F7: =B7/D7 -> 3.7610806
A8: Solei Inconew | B8: 15244.59 | C8: 26347.06 | D8: 4168.53 | E8: 182 | F8: =B8/D8 -> 3.6570662
A9: Tramonto Maxi | B9: 9422.8 | C9: 15395.59 | D9: 2355.5 | F9: =B9/D9 -> 4.0003396
A10: Grecco Maxi | B10: 11301 | C10: 18576.26 | D10: 3767 | E10: 125 | F10: =B10/D10 -> 3
A11: Liwo Working e Living Maxi | B11: 12558.41 | C11: 24288.11 | D11: 3200.58 | E11: 111 | F11: =B11/D11 -> 3.9237919
B12: =AVERAGE(B4:B5,B8,B10:B11) -> 14292.468 | C12: =AVERAGE(C4:C5,C8,C10:C11) -> 24569.154 | D12: =AVERAGE(D4:D11) -> 3728.0525 | E12: =AVERAGE(E4:E11) -> 140 | F12: =AVERAGE(F4:F11) -> 3.5902556 | G12: =C12/E12 -> 175.49396
B14: =B12/E12 -> 102.08906
